<?xml version="1.0" ?>
<robot name="panda" xmlns:xacro="http://ros.org/xacro">

  <gazebo reference="world">
    <material>Gazebo/Grey</material>
  </gazebo>

  <gazebo reference="panda_link0">
    <material>Gazebo/Grey</material>
    <selfCollide>true</selfCollide>
  </gazebo>

  <gazebo>
    <plugin name="gazebo_ros_control" filename="libgazebo_ros_control.so">
      <robotNamespace>/panda</robotNamespace>
      <robotSimType>gazebo_ros_control/DefaultRobotHWSim</robotSimType>
    </plugin>
  </gazebo>

  <link name="world" />
  <joint name="world_to_panda_link0" type="fixed">
    <parent link="world" />
    <child link="panda_link0" />
    <origin xyz="0 0 0" rpy="0 0 0" />
  </joint>

  <link name="panda_link0">
    <visual>
      <geometry>
        <mesh filename="package://franka_description/meshes/visual/link0.stl" />
      </geometry>
    </visual>
    <collision>
      <geometry>
        <mesh filename="package://franka_description/meshes/collision/link0.stl" />
      </geometry>
    </collision>
    <inertial>
      <origin xyz="0 0 0" rpy="0 0 0"/>
      <mass value="3.0"/>
      <inertia ixx="0.01" ixy="0.0" ixz="0.0" iyy="0.01" iyz="0.0" izz="0.01"/>
    </inertial>
  </link>

  <link name="panda_link0_sc">
    <inertial>
      <mass value="0.01" />
      <inertia ixx="1e-6" ixy="0" ixz="0" iyy="1e-6" iyz="0" izz="1e-6" />
      <origin xyz="0 0 0" rpy="0 0 0" />
    </inertial>
    <collision>
      <origin rpy="0 1.5707963267948966 0" xyz="-0.075 0 0.06" />
      <geometry>
        <cylinder length="0.03" radius="0.09" />
      </geometry>
    </collision>
    <collision>
      <origin xyz="-0.06 0 0.06" />
      <geometry>
        <sphere radius="0.09" />
      </geometry>
    </collision>
    <collision>
      <origin xyz="-0.09 0 0.06" />
      <geometry>
        <sphere radius="0.09" />
      </geometry>
    </collision>
  </link>
  <joint name="panda_link0_sc_joint" type="fixed">
    <origin rpy="0 0 0" xyz="0 0 0" />
    <parent link="panda_link0" />
    <child link="panda_link0_sc" />
  </joint>

  <link name="panda_link1">
    <inertial>
      <origin xyz="0 0 -0.04" rpy="0 0 0"/>
      <mass value="4.9"/>
      <inertia ixx="0.0125" ixy="0.0" ixz="0.0" iyy="0.0124" iyz="0.0" izz="0.0001"/>
    </inertial>
    <visual>
      <geometry>
        <mesh filename="package://franka_description/meshes/visual/link1.stl" />
      </geometry>
    </visual>
    <collision>
      <geometry>
        <mesh filename="package://franka_description/meshes/collision/link1.stl" />
      </geometry>
    </collision>
  </link>
  <joint name="panda_joint1" type="revolute">
    <origin xyz="0 0 0.333" rpy="0 0 0" />
    <parent link="panda_link0" />
    <child link="panda_link1" />
    <axis xyz="0 0 1" />
    <limit effort="87.0" lower="-2.8973" upper="2.8973" velocity="2.175" />
  </joint>

  <link name="panda_link2">
    <inertial>
      <origin xyz="0 0 0" rpy="0 0 0"/>
      <mass value="0.646"/>
      <inertia ixx="0.0035" ixy="0.0" ixz="0.0" iyy="0.0035" iyz="0.0" izz="0.0001"/>
    </inertial>
    <visual>
      <geometry>
        <mesh filename="package://franka_description/meshes/visual/link2.stl" />
      </geometry>
    </visual>
    <collision>
      <geometry>
        <mesh filename="package://franka_description/meshes/collision/link2.stl" />
      </geometry>
    </collision>
  </link>
  <joint name="panda_joint2" type="revolute">
    <origin xyz="0 0 0.384" rpy="0 0 0" />
    <parent link="panda_link1" />
    <child link="panda_link2" />
    <axis xyz="0 1 0" />
    <limit effort="87.0" lower="-1.7628" upper="1.7628" velocity="2.175" />
  </joint>

  <link name="panda_link3">
    <inertial>
      <origin xyz="0 0.0006 -0.04" rpy="0 0 0"/>
      <mass value="3.22"/>
      <inertia ixx="0.0063" ixy="0.0" ixz="0.0" iyy="0.0062" iyz="0.0" izz="0.0004"/>
    </inertial>
    <visual>
      <geometry>
        <mesh filename="package://franka_description/meshes/visual/link3.stl" />
      </geometry>
    </visual>
    <collision>
      <geometry>
        <mesh filename="package://franka_description/meshes/collision/link3.stl" />
      </geometry>
    </collision>
  </link>
  <joint name="panda_joint3" type="revolute">
    <origin xyz="0 0 0.107" rpy="0 0 0" />
    <parent link="panda_link2" />
    <child link="panda_link3" />
    <axis xyz="0 0 1" />
    <limit effort="87.0" lower="-2.8973" upper="2.8973" velocity="2.175" />
  </joint>

  <link name="panda_link4">
    <inertial>
      <origin xyz="0 0 0" rpy="0 0 0"/>
      <mass value="0.646"/>
      <inertia ixx="0.0035" ixy="0.0" ixz="0.0" iyy="0.0035" iyz="0.0" izz="0.0001"/>
    </inertial>
    <visual>
      <geometry>
        <mesh filename="package://franka_description/meshes/visual/link4.stl" />
      </geometry>
    </visual>
    <collision>
      <geometry>
        <mesh filename="package://franka_description/meshes/collision/link4.stl" />
      </geometry>
    </collision>
  </link>
  <joint name="panda_joint4" type="revolute">
    <origin xyz="0 0 0.106" rpy="0 0 0" />
    <parent link="panda_link3" />
    <child link="panda_link4" />
    <axis xyz="0 1 0" />
    <limit effort="12.0" lower="-2.8973" upper="2.8973" velocity="2.175" />
  </joint>

  <link name="panda_link5">
    <inertial>
      <origin xyz="0 0.0004 -0.04" rpy="0 0 0"/>
      <mass value="1.22"/>
      <inertia ixx="0.0016" ixy="0.0" ixz="0.0" iyy="0.0015" iyz="0.0" izz="0.00008"/>
    </inertial>
    <visual>
      <geometry>
        <mesh filename="package://franka_description/meshes/visual/link5.stl" />
      </geometry>
    </visual>
    <collision>
      <geometry>
        <mesh filename="package://franka_description/meshes/collision/link5.stl" />
      </geometry>
    </collision>
  </link>
  <joint name="panda_joint5" type="revolute">
    <origin xyz="0 0 0.11" rpy="0 0 0" />
    <parent link="panda_link4" />
    <child link="panda_link5" />
    <axis xyz="0 0 1" />
    <limit effort="12.0" lower="-2.8973" upper="2.8973" velocity="2.175" />
  </joint>

  <link name="panda_link6">
    <inertial>
      <origin xyz="0 0 0" rpy="0 0 0"/>
      <mass value="0.171"/>
      <inertia ixx="0.00017" ixy="0.0" ixz="0.0" iyy="0.00017" iyz="0.0" izz="0.000003"/>
    </inertial>
    <visual>
      <geometry>
        <mesh filename="package://franka_description/meshes/visual/link6.stl" />
      </geometry>
    </visual>
    <collision>
      <geometry>
        <mesh filename="package://franka_description/meshes/collision/link6.stl" />
      </geometry>
    </collision>
  </link>
  <joint name="panda_joint6" type="revolute">
    <origin xyz="0 0 0.105" rpy="0 0 0" />
    <parent link="panda_link5" />
    <child link="panda_link6" />
    <axis xyz="0 1 0" />
    <limit effort="12.0" lower="-2.8973" upper="2.8973" velocity="2.175" />
  </joint>

  <link name="panda_link7">
    <inertial>
      <origin xyz="0 0 0.01" rpy="0 0 0"/>
      <mass value="0.171"/>
      <inertia ixx="0.000012" ixy="0.0" ixz="0.0" iyy="0.000011" iyz="0.0" izz="0.000013"/>
    </inertial>
    <visual>
      <geometry>
        <mesh filename="package://franka_description/meshes/visual/link7.stl" />
      </geometry>
    </visual>
    <collision>
      <geometry>
        <mesh filename="package://franka_description/meshes/collision/link7.stl" />
      </geometry>
    </collision>
  </link>
  <joint name="panda_joint7" type="revolute">
    <origin xyz="0 0 0.1" rpy="0 0 0" />
    <parent link="panda_link6" />
    <child link="panda_link7" />
    <axis xyz="0 1 0" />
    <limit effort="12.0" lower="-2.8973" upper="2.8973" velocity="2.175" />
  </joint>

  <link name="panda_link8">
    <inertial>
      <mass value="0.01" />
      <inertia ixx="1e-6" ixy="0" ixz="0" iyy="1e-6" iyz="0" izz="1e-6" />
      <origin xyz="0 0 0" rpy="0 0 0" />
    </inertial>
  </link>
  <joint name="panda_joint8" type="fixed">
    <origin xyz="0 0 0.107" rpy="0 0 0" />
    <parent link="panda_link7" />
    <child link="panda_link8" />
  </joint>

  <link name="hand">
    <visual>
      <geometry>
        <mesh filename="package://franka_description/meshes/visual/hand.stl" />
      </geometry>
    </visual>
    <collision>
      <geometry>
        <mesh filename="package://franka_description/meshes/collision/hand.stl" />
      </geometry>
    </collision>
    <inertial>
      <origin xyz="0 0 0" rpy="0 0 0"/>
      <mass value="0.5"/>
      <inertia ixx="0.001" ixy="0.0" ixz="0.0" iyy="0.001" iyz="0.0" izz="0.001"/>
    </inertial>
  </link>
  <joint name="hand_joint" type="fixed">
    <origin xyz="0 0 0" rpy="0 0 0" />
    <parent link="panda_link8" />
    <child link="hand" />
  </joint>

  <link name="finger">
    <visual>
      <geometry>
        <mesh filename="package://franka_description/meshes/visual/finger.stl" />
      </geometry>
    </visual>
    <collision>
      <geometry>
        <mesh filename="package://franka_description/meshes/collision/finger.stl" />
      </geometry>
    </collision>
    <inertial>
      <origin xyz="0 0 0" rpy="0 0 0"/>
      <mass value="0.05"/>
      <inertia ixx="0.00001" ixy="0.0" ixz="0.0" iyy="0.00001" iyz="0.0" izz="0.00001"/>
    </inertial>
  </link>

  <joint name="finger_joint" type="prismatic">
    <origin xyz="0 0 0" rpy="0 0 0" />
    <parent link="hand" />
    <child link="finger" />
    <axis xyz="1 0 0" />
    <limit effort="100" lower="0.0" upper="0.04" velocity="0.1" />
  </joint>

  <transmission name="trans_panda_joint1">
    <type>transmission_interface/SimpleTransmission</type>
    <joint name="panda_joint1">
      <hardwareInterface>hardware_interface/EffortJointInterface</hardwareInterface>
    </joint>
    <actuator name="panda_joint1_motor">
      <hardwareInterface>hardware_interface/EffortJointInterface</hardwareInterface>
      <mechanicalReduction>1</mechanicalReduction>
    </actuator>
  </transmission>
  <transmission name="trans_panda_joint2">
    <type>transmission_interface/SimpleTransmission</type>
    <joint name="panda_joint2">
      <hardwareInterface>hardware_interface/EffortJointInterface</hardwareInterface>
    </joint>
    <actuator name="panda_joint2_motor">
      <hardwareInterface>hardware_interface/EffortJointInterface</hardwareInterface>
      <mechanicalReduction>1</mechanicalReduction>
    </actuator>
  </transmission>
  <transmission name="trans_panda_joint3">
    <type>transmission_interface/SimpleTransmission</type>
    <joint name="panda_joint3">
      <hardwareInterface>hardware_interface/EffortJointInterface</hardwareInterface>
    </joint>
    <actuator name="panda_joint3_motor">
      <hardwareInterface>hardware_interface/EffortJointInterface</hardwareInterface>
      <mechanicalReduction>1</mechanicalReduction>
    </actuator>
  </transmission>
  <transmission name="trans_panda_joint4">
    <type>transmission_interface/SimpleTransmission</type>
    <joint name="panda_joint4">
      <hardwareInterface>hardware_interface/EffortJointInterface</hardwareInterface>
    </joint>
    <actuator name="panda_joint4_motor">
      <hardwareInterface>hardware_interface/EffortJointInterface</hardwareInterface>
      <mechanicalReduction>1</mechanicalReduction>
    </actuator>
  </transmission>
  <transmission name="trans_panda_joint5">
    <type>transmission_interface/SimpleTransmission</type>
    <joint name="panda_joint5">
      <hardwareInterface>hardware_interface/EffortJointInterface</hardwareInterface>
    </joint>
    <actuator name="panda_joint5_motor">
      <hardwareInterface>hardware_interface/EffortJointInterface</hardwareInterface>
      <mechanicalReduction>1</mechanicalReduction>
    </actuator>
  </transmission>
  <transmission name="trans_panda_joint6">
    <type>transmission_interface/SimpleTransmission</type>
    <joint name="panda_joint6">
      <hardwareInterface>hardware_interface/EffortJointInterface</hardwareInterface>
    </joint>
    <actuator name="panda_joint6_motor">
      <hardwareInterface>hardware_interface/EffortJointInterface</hardwareInterface>
      <mechanicalReduction>1</mechanicalReduction>
    </actuator>
  </transmission>
  <transmission name="trans_panda_joint7">
    <type>transmission_interface/SimpleTransmission</type>
    <joint name="panda_joint7">
      <hardwareInterface>hardware_interface/EffortJointInterface</hardwareInterface>
    </joint>
    <actuator name="panda_joint7_motor">
      <hardwareInterface>hardware_interface/EffortJointInterface</hardwareInterface>
      <mechanicalReduction>1</mechanicalReduction>
    </actuator>
  </transmission>

  <transmission name="trans_finger_joint">
    <type>transmission_interface/SimpleTransmission</type>
    <joint name="finger_joint">
      <hardwareInterface>hardware_interface/EffortJointInterface</hardwareInterface>
    </joint>
    <actuator name="finger_joint_motor">
      <hardwareInterface>hardware_interface/EffortJointInterface</hardwareInterface>
      <mechanicalReduction>1</mechanicalReduction>
    </actuator>
  </transmission>

</robot>
